<!DOCTYPE html>
<html lang="en">

<head>
    <meta charset="UTF-8">
    <title>Promise详解</title>
</head>

<body>
    <div>
        <dl>
            <dt>Promise 的基本特征</dt>
            <dd>1.promise 有三个状态：pending，fulfilled，rejected</dd>
            <dd>2.new promise时，需要传递一个executor()执行器，执行器立即执行</dd>
            <dd>3.executor接受两个参数，分别是resolve和reject</dd>
            <dd>4.promise 的默认状态是 pending</dd>
            <dd>5.promise 有一个value保存成功状态的值，可以是undefined/thenable/promise</dd>
            <dd>6.promise 有一个reason保存失败状态的值</dd>
            <dd>7.promise 只能从pending到rejected, 或者从pending到fulfilled，状态一旦确认，就不会再改变</dd>
            <dd>8.promise 必须有一个then方法，then 接收两个参数，分别是 promise 成功的回调 onFulfilled, 和 promise 失败的回调 onRejected</dd>
            <dd>9.如果调用 then 时，promise 已经成功，则执行onFulfilled，参数是promise的value</dd>
            <dd>10.如果调用 then 时，promise 已经成功，则执行onFulfilled，参数是promise的value</dd>
            <dd>11.如果调用 then 时，promise 已经失败，那么执行onRejected, 参数是promise的reason</dd>
            <dd>12.如果 then 中抛出了异常，那么就会把这个异常作为参数，传递给下一个 then 的失败的回调onRejected</dd>
        </dl>
    </div>

    <script>
        // 参考 https://zhuanlan.zhihu.com/p/183801144
        const PENDING = 'PENDING';
        const FULFILLED = 'FULFILLED';
        const REJECTED = 'REJECTED';

        const resolvePromise = (promise2, x, resolve, reject) => {
            // 自己等待自己完成是错误的实现，用一个类型错误，结束掉 promise  Promise/A+ 2.3.1
            if (promise2 === x) {
                return reject(new TypeError('Chaining cycle detected for promise #<Promise>'))
            }
            // Promise/A+ 2.3.3.3.3 只能调用一次
            let called;
            // 后续的条件要严格判断 保证代码能和别的库一起使用
            if ((typeof x === 'object' && x != null) || typeof x === 'function') {
                try {
                    // 为了判断 resolve 过的就不用再 reject 了（比如 reject 和 resolve 同时调用的时候）  Promise/A+ 2.3.3.1
                    let then = x.then;
                    if (typeof then === 'function') {
                        // 不要写成 x.then，直接 then.call 就可以了 因为 x.then 会再次取值，Object.defineProperty  Promise/A+ 2.3.3.3
                        then.call(x, y => { // 根据 promise 的状态决定是成功还是失败
                            if (called) return;
                            called = true;
                            // 递归解析的过程（因为可能 promise 中还有 promise） Promise/A+ 2.3.3.3.1
                            resolvePromise(promise2, y, resolve, reject);
                        }, r => {
                            // 只要失败就失败 Promise/A+ 2.3.3.3.2
                            if (called) return;
                            called = true;
                            reject(r);
                        });
                    } else {
                        // 如果 x.then 是个普通值就直接返回 resolve 作为结果  Promise/A+ 2.3.3.4
                        resolve(x);
                    }
                } catch (e) {
                    // Promise/A+ 2.3.3.2
                    if (called) return;
                    called = true;
                    reject(e)
                }
            } else {
                // 如果 x 是个普通值就直接返回 resolve 作为结果  Promise/A+ 2.3.4  
                resolve(x)
            }
        }

        class Promise {
            constructor(executor) {
                this.status = PENDING;
                this.value = undefined;
                this.reason = undefined;
                this.onResolvedCallbacks = [];
                this.onRejectedCallbacks = [];

                let resolve = (value) => {
                    if (this.status === PENDING) {
                        this.status = FULFILLED;
                        this.value = value;
                        this.onResolvedCallbacks.forEach(fn => fn());
                    }
                }

                let reject = (reason) => {
                    if (this.status === PENDING) {
                        this.status = REJECTED;
                        this.reason = reason;
                        this.onRejectedCallbacks.forEach(fn => fn());
                    }
                }

                try {
                    executor(resolve, reject)
                } catch (error) {
                    reject(error)
                }
            }

            // 基本的promise，不能then(res).then(res), 不能值穿透
            // then(onFulFilled, onReject) {
            // if (this.status === FULFILLED) {
            //     onFulFilled(this.value)
            // }
            // if (this.status === REJECTED) {
            //     onReject(this.reason)
            // }
            // if (this.status === PENDING) {
            //     this.callbackSuccessList.push(() => onFulFilled(this.value))
            //     this.callbackFailedList.push(() => onReject(this.reason))
            // }
            // }

            then(onFulfilled, onRejected) {
                //解决 onFufilled，onRejected 没有传值的问题
                //Promise/A+ 2.2.1 / Promise/A+ 2.2.5 / Promise/A+ 2.2.7.3 / Promise/A+ 2.2.7.4
                onFulfilled = typeof onFulfilled === 'function' ? onFulfilled : v => v;
                //因为错误的值要让后面访问到，所以这里也要跑出个错误，不然会在之后 then 的 resolve 中捕获
                onRejected = typeof onRejected === 'function' ? onRejected : err => {
                    throw err
                };
                // 每次调用 then 都返回一个新的 promise  Promise/A+ 2.2.7
                let promise2 = new Promise((resolve, reject) => {
                    if (this.status === FULFILLED) {
                        //Promise/A+ 2.2.2
                        //Promise/A+ 2.2.4 --- setTimeout
                        setTimeout(() => {
                            try {
                                //Promise/A+ 2.2.7.1
                                let x = onFulfilled(this.value);
                                // x可能是一个proimise
                                resolvePromise(promise2, x, resolve, reject);
                            } catch (e) {
                                //Promise/A+ 2.2.7.2
                                reject(e)
                            }
                        }, 0);
                    }

                    if (this.status === REJECTED) {
                        //Promise/A+ 2.2.3
                        setTimeout(() => {
                            try {
                                let x = onRejected(this.reason);
                                resolvePromise(promise2, x, resolve, reject);
                            } catch (e) {
                                reject(e)
                            }
                        }, 0);
                    }

                    if (this.status === PENDING) {
                        this.onResolvedCallbacks.push(() => {
                            setTimeout(() => {
                                try {
                                    let x = onFulfilled(this.value);
                                    resolvePromise(promise2, x, resolve, reject);
                                } catch (e) {
                                    reject(e)
                                }
                            }, 0);
                        });

                        this.onRejectedCallbacks.push(() => {
                            setTimeout(() => {
                                try {
                                    let x = onRejected(this.reason);
                                    resolvePromise(promise2, x, resolve, reject)
                                } catch (e) {
                                    reject(e)
                                }
                            }, 0);
                        });
                    }
                });

                return promise2;
            }
        }

        const promise = new Promise((resolve, reject) => {
            resolve('success');
        }).then(res => {
            res = res + '!'
            return res
        }).then(data => {
            console.log(data);
        }, err => {
            console.log('err', err);
        })
    </script>
</body>

</html>